Workbook

Sheet Contents (Índice)
D20: Nu Holdings Ltd.
D21: Investor Relations
D22: investors@nubank.com.br
B24: MANAGERIAL INFORMATION | F24: CONSOLIDATED FINANCIAL STATEMENTS IN IFRS
B26: Managerial P&L | F26: Consolidated Statement of Income
B27: Managerial Indicators | F27: Consolidated Balance Sheet
B28: Operating Figures | F28: Consolidated Statement of Cash Flow
B29: Non-Performing Loans (NPLs) | F29: Revenue Breakdown
F30: Expenses Breakdown
F31: Credit Operations

Sheet Managerial P&L 
B2: Nu Holdings Ltd.
B3: Managerial Indicators
B4: Amounts in million of US$, unless otherwise noted
B5: Back to Contents
C8: 3-MONTH PERIOD ENDED
C9: 44286 | D9: 44377 | E9: 44469 | F9: 44561 | G9: 44651 | H9: 44742 | I9: 44834 | J9: 44926 | K9: 45016 | L9: 45107 | M9: 45199 | N9: 31/12/2023 | O9: 31/03/2024 | P9: 30/06/2024 | Q9: 30/09/2024 | R9: 31/12/2024 | S9: 31/03/2025 | T9: 30/06/2025 | U9: 30/09/2025 | V9: 31/12/2025
C10: US$ | D10: US$ | E10: US$ | F10: US$ | G10: US$ | H10: US$ | I10: US$ | J10: US$ | K10: US$ | L10: US$ | M10: US$ | N10: US$ | O10: US$ | P10: US$ | Q10: US$ | R10: US$ | S10: US$ | T10: US$ | U10: US$ | V10: US$
B11: Total Revenue | C11: 247.185 | D11: 338.62 | E11: 483.044 | F11: 591.206 | G11: 879.075 | H11: 1163.24 | I11: 1316.162 | J11: 1463.394 | K11: 1632.23 | L11: 1892.365 | M11: 2171.312 | N11: 2455.115 | O11: 2722.923 | P11: 2877.952 | Q11: 2969.534 | R11: 3100.702 | S11: 3372.725 | T11: 3772.305 | U11: 4317.219 | V11: 4857.306
B12: Credit Income | C12: 90.962 | D12: 130.2 | E12: 178.633 | F12: 203.839 | G12: 383.667 | H12: 471.951 | I12: 512.65 | J12: 578.803 | K12: 734.639 | L12: 946.937 | M12: 1144.058 | N12: 1388.524 | O12: 1608.779 | P12: 1736.527 | Q12: 1740.306 | R12: 1783.591 | S12: 1976.011 | T12: 2239.789 | U12: 2489.195 | V12: 2777.963
B13: Float Income | C13: 36.477 | D13: 54.859 | E13: 116.687 | F13: 189.163 | G13: 235.85 | H13: 384.502 | I13: 482.546 | J13: 527.111 | K13: 531.88 | L13: 572.919 | M13: 617.077 | N13: 609.956 | O13: 655.605 | P13: 690.009 | Q13: 761.229 | R13: 806.365 | S13: 880.142 | T13: 990.931 | U13: 1225.272 | V13: 1408.906
B14: Fee Revenue | C14: 119.746 | D14: 153.561 | E14: 187.724 | F14: 198.204 | G14: 259.558 | H14: 306.787 | I14: 320.966 | J14: 357.48 | K14: 365.712 | L14: 372.509 | M14: 410.177 | N14: 456.634 | O14: 458.539 | P14: 451.416 | Q14: 467.999 | R14: 510.746 | S14: 516.572 | T14: 541.585 | U14: 602.752 | V14: 670.437
B16: Total Direct Costs | C16: -132.93 | D16: -173.508 | E16: -260.977 | F16: -414.396 | G16: -590.192 | H16: -843.409 | I16: -912.31 | J16: -913.332 | K16: -1013.067 | L16: -1143.331 | M16: -1302.73 | N16: -1371.509 | O16: -1609.409 | P16: -1584.712 | Q16: -1667.82 | R16: -1783.674 | S16: -2045.202 | T16: -2252.982 | U16: -2506.032 | V16: -2896.24
B17: Funding Cost | C17: -29.067 | D17: -53.886 | E17: -95.458 | F17: -159.158 | G17: -256.243 | H17: -376.357 | I17: -451.034 | J17: -395.735 | K17: -429.426 | L17: -438.676 | M17: -510.492 | N17: -530.431 | O17: -599.603 | P17: -648.426 | Q17: -713.321 | R17: -761.83 | S17: -841.09 | T17: -1007.269 | U17: -1237.186 | V17: -1349.973
B18: Cost of Credit | C18: -73.97 | D18: -86.018 | E18: -132.94 | F18: -217.49 | G18: -292.482 | H18: -369.635 | I18: -384.329 | J18: -426.999 | K18: -485.581 | L18: -605.184 | M18: -664.483 | N18: -700.867 | O18: -863.359 | P18: -783.74 | Q18: -801.918 | R18: -849.905 | S18: -1041.848 | T18: -1051.053 | U18: -1035.802 | V18: -1313.223
B19: Transaction Cost | C19: -28.377 | D19: -32.148 | E19: -30.335 | F19: -34.217 | G19: -36.182 | H19: -50.275 | I19: -45.822 | J19: -51.921 | K19: -55.277 | L19: -46.891 | M19: -63.97 | N19: -64.51 | O19: -63.551 | P19: -64.511 | Q19: -64.427 | R19: -79.921 | S19: -63.082 | T19: -83.232 | U19: -108.227 | V19: -99.019
B20: Revenue-Based Taxes | C20: -1.516 | D20: -1.456 | E20: -2.244 | F20: -3.531 | G20: -5.285 | H20: -47.142 | I20: -31.125 | J20: -38.676 | K20: -42.783 | L20: -52.58 | M20: -63.786 | N20: -75.702 | O20: -82.896 | P20: -88.035 | Q20: -88.154 | R20: -92.019 | S20: -99.182 | T20: -111.428 | U20: -124.818 | V20: -134.025
B22: Gross Profit | C22: 114.255 | D22: 165.112 | E22: 222.067 | F22: 176.81 | G22: 288.883 | H22: 319.831 | I22: 403.852 | J22: 550.063 | K22: 619.164 | L22: 749.034 | M22: 868.583 | N22: 1083.605 | O22: 1113.514 | P22: 1293.241 | Q22: 1301.714 | R22: 1317.028 | S22: 1327.524 | T22: 1519.323 | U22: 1811.187 | V22: 1961.065
B24: Operating Expenses | C24: -167.585 | D24: -171.575 | E24: -243.681 | F24: -307.914 | G24: -356.503 | H24: -342.734 | I24: -389.448 | J24: -756.441 | K24: -366.409 | L24: -411.591 | M24: -436.829 | N24: -488.042 | O24: -522.728 | P24: -540.185 | Q24: -520.319 | R24: -469.372 | S24: -459.203 | T24: -548.104 | U24: -577.193 | V24: -652.635
B25: Customer Support and Operations | C25: -32.13 | D25: -40.968 | E25: -51.649 | F25: -65.762 | G25: -61.571 | H25: -77.703 | I25: -90.249 | J25: -105.84 | K25: -107.815 | L25: -113.309 | M25: -127.295 | N25: -139.663 | O25: -150.612 | P25: -162.917 | Q25: -135.196 | R25: -155.918 | S25: -151.475 | T25: -161.434 | U25: -174.843 | V25: -164.008
... B36: Net Income | C36: -49.483 | D36: -15.22 | E36: -34.357 | F36: -113.172 | G36: -45.004 | H36: -29.85 | I36: 7.833 | J36: -297.613 | K36: 141.751 | L36: 224.866 | M36: 303.036 | N36: 360.877 | O36: 378.814 | P36: 487.272 | Q36: 553.386 | R36: 552.64 | S36: 557.208 | T36: 636.987 | U36: 782.678 | V36: 894.799

Sheet Managerial indicators
B2: Nu Holdings Ltd.
B3: Managerial Indicators
B4: Amounts in million of US$, unless otherwise noted
B5: Back to Contents
C9: 44286 | D9: 44377 | E9: 44469 | F9: 44561 | G9: 44651 | H9: 44742 | I9: 44834 | J9: 44926 | K9: 45016 | L9: 45107 | M9: 45199 | N9: 31/12/2023 | O9: 31/03/2024 | P9: 30/06/2024 | Q9: 30/09/2024 | R9: 31/12/2024 | S9: 31/03/2025 | T9: 30/06/2025 | U9: 30/09/2025 | V9: 31/12/2025
C10: US$ | D10: US$ | E10: US$ | F10: US$ | G10: US$ | H10: US$ | I10: US$ | J10: US$ | K10: US$ | L10: US$ | M10: US$ | N10: US$ | O10: US$ | P10: US$ | Q10: US$ | R10: US$ | S10: US$ | T10: US$ | U10: US$ | V10: US$
B11: Average Revenue per Active Customer (ARPAC) - US$ | C11: 3.2 | D11: 4.1 | E11: 4.9 | F11: 5.2 | G11: 6.7 | H11: 7.8 | I11: 8 | J11: 8.2 | K11: 8.6 | L11: 9.4 | M11: 10.2 | N11: 10.8 | O11: 11.3 | P11: 11.3 | Q11: 11.1 | R11: 11.1 | S11: 11.6 | T11: 12.5 | U11: 13.8 | V11: 15
B13: Cost to Serve per Active Customer - US$ | C13: 0.8 | D13: 0.9 | E13: 0.8 | F13: 0.9 | G13: 0.7 | H13: 0.9 | I13: 0.8 | J13: 0.9 | K13: 0.9 | L13: 0.8 | M13: 0.9 | N13: 0.9 | O13: 0.9 | P13: 0.9 | Q13: 0.7 | R13: 0.8 | S13: 0.7 | T13: 0.8 | U13: 0.9 | V13: 0.8
B15: Balances EoP
B16: Credit Card non-IEP | C16: 2668 | D16: 3659 | E16: 3855 | F16: 4513 | G16: 5736 | H16: 5866 | I16: 6119 | J16: 7136 | K16: 7641 | L16: 8524 | M16: 8484 | N16: 9980 | O16: 9862 | P16: 9098 | Q16: 9669 | R16: 9522 | S16: 10281 | T16: 11595 | U16: 12678 | V16: 14181
B17: Credit Card IEP | C17: 327 | D17: 428 | E17: 512 | F17: 646 | G17: 1067 | H17: 1298 | I17: 1681 | J17: 2131 | K17: 2814 | L17: 3512 | M17: 3832 | N17: 4508 | O17: 5232 | P17: 5217 | Q17: 5518 | R17: 5097 | S17: 5988 | T17: 6630 | U17: 7350 | V17: 7570
B18: Loans to customers | C18: 304 | D18: 592 | E18: 903 | F18: 1392 | G18: 2009 | H18: 1953 | I18: 1907 | J18: 1976 | K18: 2337 | L18: 2792 | M18: 3091 | N18: 3714 | O18: 4479 | P18: 4632 | Q18: 5692 | R18: 6116 | S18: 7848 | T18: 9056 | U18: 10362 | V18: 10915
B19: Total Interest Earning Portfolio (IEP) | C19: =C17+C18 -> 631 | D19: =D17+D18 -> 1020 | E19: =E17+E18 -> 1415 | F19: =F17+F18 -> 2038 | G19: =G17+G18 -> 3076 | H19: =H17+H18 -> 3251 | I19: =I17+I18 -> 3588 | J19: =J17+J18 -> 4107 | ... V19: =V17+V18 -> 18485
B21: Cash and cash equivalents | C21: ='IFRS - Balance Sheet'!E12 -> 2200.663 | D21: ='IFRS - Balance Sheet'!F12 -> 2662.467 | E21: ='IFRS - Balance Sheet'!G12 -> 1996.725 | F21: ='IFRS - Balance Sheet'!H12 -> 2705.675 | G21: ='IFRS - Balance Sheet'!I12 -> 2968.622 | H21: ='IFRS - Balance Sheet'!J12 -> 3701.02 | I21: ='IFRS - Balance Sheet'!K12 -> 3692.793 | J21: ='IFRS - Balance Sheet'!L12 -> 4172.316 | ... V21: ='IFRS - Balance Sheet'!X12 -> 15003.643
B22: Securities - Financial assets at fair value through profit or loss | C22: ='IFRS - Balance Sheet'!E14 -> 4356.451 | D22: ='IFRS - Balance Sheet'!F14 -> 5343.289 | E22: ='IFRS - Balance Sheet'!G14 -> 4680.014 | F22: ='IFRS - Balance Sheet'!H14 -> 815.962 | G22: ='IFRS - Balance Sheet'!I14 -> 817.443 | H22: ='IFRS - Balance Sheet'!J14 -> 856.994 | I22: ='IFRS - Balance Sheet'!K14 -> 740.972 | J22: ='IFRS - Balance Sheet'!L14 -> 91.853 | ... V22: ='IFRS - Balance Sheet'!X14 -> 1059.923
B23: Securities - Financial assets at fair value through OCI | C23: ='IFRS - Balance Sheet'!E18 -> 0 | D23: ='IFRS - Balance Sheet'!F18 -> 348.518 | E23: ='IFRS - Balance Sheet'!G18 -> 1837.715 | F23: ='IFRS - Balance Sheet'!H18 -> 8163.428 | G23: ='IFRS - Balance Sheet'!I18 -> 9260.432 | H23: ='IFRS - Balance Sheet'!J18 -> 8850.741 | I23: ='IFRS - Balance Sheet'!K18 -> 8931.961 | J23: ='IFRS - Balance Sheet'!L18 -> 9947.138 | ... V23: ='IFRS - Balance Sheet'!X18 -> 12157.076
B24: Securities - Financial assets at amortized cost | C24: ='IFRS - Balance Sheet'!E25 -> 0 | D24: ='IFRS - Balance Sheet'!F25 -> 0 | E24: ='IFRS - Balance Sheet'!G25 -> 0 | F24: ='IFRS - Balance Sheet'!H25 -> 0 | G24: ='IFRS - Balance Sheet'!I25 -> 0 | H24: ='IFRS - Balance Sheet'!J25 -> 0 | I24: ='IFRS - Balance Sheet'!K25 -> 0 | J24: ='IFRS - Balance Sheet'!L25 -> 0 | ... V24: ='IFRS - Balance Sheet'!X25 -> 3141.504
B25: Compulsory and other deposits at central banks | C25: ='IFRS - Balance Sheet'!E22 -> 98.694 | D25: ='IFRS - Balance Sheet'!F22 -> 265.465 | E25: ='IFRS - Balance Sheet'!G22 -> 422.649 | F25: ='IFRS - Balance Sheet'!H22 -> 938.659 | G25: ='IFRS - Balance Sheet'!I22 -> 1333.427 | H25: ='IFRS - Balance Sheet'!J22 -> 1552.139 | I25: ='IFRS - Balance Sheet'!K22 -> 1860.438 | J25: ='IFRS - Balance Sheet'!L22 -> 2778.019 | ... V25: ='IFRS - Balance Sheet'!X22 -> 9537.788
B26: Other receivables | C26: ='IFRS - Balance Sheet'!E26 -> 0 | D26: ='IFRS - Balance Sheet'!F26 -> 0 | E26: ='IFRS - Balance Sheet'!G26 -> 0 | F26: ='IFRS - Balance Sheet'!H26 -> 50.349 | G26: ='IFRS - Balance Sheet'!I26 -> 285.632 | H26: ='IFRS - Balance Sheet'!J26 -> 374.188 | I26: ='IFRS - Balance Sheet'!K26 -> 381.782 | J26: ='IFRS - Balance Sheet'!L26 -> 521.67 | ... V26: ='IFRS - Balance Sheet'!X26 -> 1000.683
B27: Other financial assets | C27: ='IFRS - Balance Sheet'!E27 -> 19.896 | D27: ='IFRS - Balance Sheet'!F27 -> 24.899 | E27: ='IFRS - Balance Sheet'!G27 -> 39.228 | F27: ='IFRS - Balance Sheet'!H27 -> 18.493 | G27: ='IFRS - Balance Sheet'!I27 -> 49.739 | H27: ='IFRS - Balance Sheet'!J27 -> 61.136 | I27: ='IFRS - Balance Sheet'!K27 -> 75.591 | J27: ='IFRS - Balance Sheet'!L27 -> 478.283 | ... V27: ='IFRS - Balance Sheet'!X27 -> 148.777
B28: Derivatives | C28: ='IFRS - Balance Sheet'!E15 -> 0.034 | D28: ='IFRS - Balance Sheet'!F15 -> 5.845 | E28: ='IFRS - Balance Sheet'!G15 -> 89.543 | F28: ='IFRS - Balance Sheet'!H15 -> 101.318 | G28: ='IFRS - Balance Sheet'!I15 -> 209.439 | H28: ='IFRS - Balance Sheet'!J15 -> 109.934 | I28: ='IFRS - Balance Sheet'!K15 -> 39.552 | J28: ='IFRS - Balance Sheet'!L15 -> 41.485 | ... V28: ='IFRS - Balance Sheet'!X15 -> 80.748
B29: Collateral for credit card operations | C29: ='IFRS - Balance Sheet'!E16 -> 49.092 | D29: ='IFRS - Balance Sheet'!F16 -> 41.082 | E29: ='IFRS - Balance Sheet'!G16 -> 11.379 | F29: ='IFRS - Balance Sheet'!H16 -> 1.052 | G29: ='IFRS - Balance Sheet'!I16 -> 10.173 | H29: ='IFRS - Balance Sheet'!J16 -> 0.401 | I29: ='IFRS - Balance Sheet'!K16 -> 0.303 | J29: ='IFRS - Balance Sheet'!L16 -> 0.305 | ... V29: ='IFRS - Balance Sheet'!X16 -> 0
B30: Total Interest Earning Assets (IEA) | C30: =SUM(C21:C29,C19) -> 7355.83 | D30: =SUM(D21:D29,D19) -> 9711.565 | E30: =SUM(E21:E29,E19) -> 10492.253 | F30: =SUM(F21:F29,F19) -> 14832.936 | G30: =SUM(G21:G29,G19) -> 18010.907 | H30: =SUM(H21:H29,H19) -> 18757.553 | I30: =SUM(I21:I29,I19) -> 19311.392 | J30: =SUM(J21:J29,J19) -> 22138.069 | ... V30: =SUM(V21:V29,V19) -> 60615.142
B32: Average Balance
B33: Total Interest Earning Assets (IEA) | D33: =AVERAGE(C30:D30) -> 8533.6975 | E33: =AVERAGE(D30:E30) -> 10101.909 | F33: =AVERAGE(E30:F30) -> 12662.594 | G33: =AVERAGE(F30:G30) -> 16421.922 | H33: =AVERAGE(G30:H30) -> 18384.23 | I33: =AVERAGE(H30:I30) -> 19034.472 | J33: =AVERAGE(I30:J30) -> 20724.731 | K33: =AVERAGE(J30:K30) -> 21737.841 | ... V33: =AVERAGE(U30:V30) -> 58118.014
B35: Interest Income, Expense and Cost of Risk
B36: Credit Income | C36: ='Managerial P&L '!C12 -> 90.962 | D36: ='Managerial P&L '!D12 -> 130.2 | E36: ='Managerial P&L '!E12 -> 178.633 | F36: ='Managerial P&L '!F12 -> 203.839 | G36: ='Managerial P&L '!G12 -> 383.667 | H36: ='Managerial P&L '!H12 -> 471.951 | I36: ='Managerial P&L '!I12 -> 512.65 | J36: ='Managerial P&L '!J12 -> 578.803 | ... V36: ='Managerial P&L '!V12 -> 2777.963
B37: Float Income | C37: ='Managerial P&L '!C13 -> 36.477 | D37: ='Managerial P&L '!D13 -> 54.859 | E37: ='Managerial P&L '!E13 -> 116.687 | F37: ='Managerial P&L '!F13 -> 189.163 | G37: ='Managerial P&L '!G13 -> 235.85 | H37: ='Managerial P&L '!H13 -> 384.502 | I37: ='Managerial P&L '!I13 -> 482.546 | J37: ='Managerial P&L '!J13 -> 527.111 | ... V37: ='Managerial P&L '!V13 -> 1408.906
B38: Funding Cost | C38: ='Managerial P&L '!C17 -> -29.067 | D38: ='Managerial P&L '!D17 -> -53.886 | E38: ='Managerial P&L '!E17 -> -95.458 | F38: ='Managerial P&L '!F17 -> -159.158 | G38: ='Managerial P&L '!G17 -> -256.243 | H38: ='Managerial P&L '!H17 -> -376.357 | I38: ='Managerial P&L '!I17 -> -451.034 | J38: ='Managerial P&L '!J17 -> -395.735 | ... V38: ='Managerial P&L '!V17 -> -1349.973
B39: NII | C39: =SUM(C36:C38) -> 98.372 | D39: =SUM(D36:D38) -> 131.173 | E39: =SUM(E36:E38) -> 199.862 | F39: =SUM(F36:F38) -> 233.844 | G39: =SUM(G36:G38) -> 363.274 | H39: =SUM(H36:H38) -> 480.096 | I39: =SUM(I36:I38) -> 544.162 | J39: =SUM(J36:J38) -> 710.179 | ... V39: =SUM(V36:V38) -> 2836.896
B40: Cost of Credit | C40: ='Managerial P&L '!C18 -> -73.97 | D40: ='Managerial P&L '!D18 -> -86.018 | E40: ='Managerial P&L '!E18 -> -132.94 | F40: ='Managerial P&L '!F18 -> -217.49 | G40: ='Managerial P&L '!G18 -> -292.482 | H40: ='Managerial P&L '!H18 -> -369.635 | I40: ='Managerial P&L '!I18 -> -384.329 | J40: ='Managerial P&L '!J18 -> -426.999 | ... V40: ='Managerial P&L '!V18 -> -1313.223
B41: Risk-adjusted NII | C41: =C39+C40 -> 24.402 | D41: =D39+D40 -> 45.155 | E41: =E39+E40 -> 66.922 | F41: =F39+F40 -> 16.354 | G41: =G39+G40 -> 70.792 | H41: =H39+H40 -> 110.461 | I41: =I39+I40 -> 159.833 | J41: =J39+J40 -> 283.18 | ... V41: =V39+V40 -> 1523.673
B43: Margin (%)
B44: Risk-adjusted NIM (%) | D44: =D41/D33*4 -> 0.021165503 | E44: =E41/E33*4 -> 0.026498754 | F44: =F41/F33*4 -> 0.0051660819 | G44: =G41/G33*4 -> 0.017243293 | H44: =H41/H33*4 -> 0.024033859 | I44: =I41/I33*4 -> 0.033588112 | J44: =J41/J33*4 -> 0.054655476 | K44: =K41/K33*4 -> 0.064682045 | ... V44: =V41/V33*4 -> 0.10486752
B46: Efficiency Ratio (%)
B47: Operating Expenses | C47: =-'Managerial P&L '!C24 -> 167.585 | D47: =-'Managerial P&L '!D24 -> 171.575 | E47: =-'Managerial P&L '!E24 -> 243.681 | F47: =-'Managerial P&L '!F24 -> 307.914 | G47: =-'Managerial P&L '!G24 -> 356.503 | H47: =-'Managerial P&L '!H24 -> 342.734 | I47: =-'Managerial P&L '!I24 -> 389.448 | J47: =-'Managerial P&L '!J24 -> 756.441 | ... V47: =-'Managerial P&L '!V24 -> 652.635
B48: Total Revenue | C48: ='Managerial P&L '!C11 -> 247.185 | D48: ='Managerial P&L '!D11 -> 338.62 | E48: ='Managerial P&L '!E11 -> 483.044 | F48: ='Managerial P&L '!F11 -> 591.206 | G48: ='Managerial P&L '!G11 -> 879.075 | H48: ='Managerial P&L '!H11 -> 1163.24 | I48: ='Managerial P&L '!I11 -> 1316.162 | J48: ='Managerial P&L '!J11 -> 1463.394 | ... V48: ='Managerial P&L '!V11 -> 4857.306
B49: Funding Cost | C49: ='Managerial P&L '!C17 -> -29.067 | D49: ='Managerial P&L '!D17 -> -53.886 | E49: ='Managerial P&L '!E17 -> -95.458 | F49: ='Managerial P&L '!F17 -> -159.158 | G49: ='Managerial P&L '!G17 -> -256.243 | H49: ='Managerial P&L '!H17 -> -376.357 | I49: ='Managerial P&L '!I17 -> -451.034 | J49: ='Managerial P&L '!J17 -> -395.735 | ... V49: ='Managerial P&L '!V17 -> -1349.973
B50: Transaction Cost | C50: ='Managerial P&L '!C19 -> -28.377 | D50: ='Managerial P&L '!D19 -> -32.148 | E50: ='Managerial P&L '!E19 -> -30.335 | F50: ='Managerial P&L '!F19 -> -34.217 | G50: ='Managerial P&L '!G19 -> -36.182 | H50: ='Managerial P&L '!H19 -> -50.275 | I50: ='Managerial P&L '!I19 -> -45.822 | J50: ='Managerial P&L '!J19 -> -51.921 | ... V50: ='Managerial P&L '!V19 -> -99.019
B51: Revenue-Based Taxes | C51: ='Managerial P&L '!C20 -> -1.516 | D51: ='Managerial P&L '!D20 -> -1.456 | E51: ='Managerial P&L '!E20 -> -2.244 | F51: ='Managerial P&L '!F20 -> -3.531 | G51: ='Managerial P&L '!G20 -> -5.285 | H51: ='Managerial P&L '!H20 -> -47.142 | I51: ='Managerial P&L '!I20 -> -31.125 | J51: ='Managerial P&L '!J20 -> -38.676 | ... V51: ='Managerial P&L '!V20 -> -134.025
...

Sheet Operating figures
B2: Nu Holdings Ltd.
B3: Operating Figures
B4: Amounts in billion of US$, unless otherwise noted
B5: Back to Contents
C9: 43921 | D9: 44012 | E9: 44104 | F9: 44196 | G9: 44286 | H9: 44377 | I9: 44469 | J9: 44561 | K9: 44651 | L9: 44742 | M9: 44834 | N9: 44926 | O9: 45016 | P9: 30/06/2023 | Q9: 30/09/2023 | R9: 31/12/2023 | S9: 31/03/2024 | T9: 30/06/2024 | U9: 30/09/2024 | V9: 31/12/2024 | W9: 31/03/2025 | X9: 30/06/2025 | Y9: 30/09/2025 | Z9: 31/12/2025
B10: Number of customers (# MM)
B11: Brazil | C11: 23.5 | D11: 26.1 | E11: 29.7 | F11: 33.2 | G11: 36.9 | H11: 41.3 | I11: 47.3 | J11: 52.4 | K11: 57.3 | L11: 62.3 | M11: 66.9 | N11: 70.9 | O11: 75.3 | P11: 79.4 | Q11: 84 | R11: 87.9 | S11: 91.8 | T11: 95.5 | U11: 98.8 | V11: 101.8 | W11: 104.6 | X11: 107.3 | Y11: 110.1 | Z11: 112.7
B12: Individual | C12: 23.3 | D12: 25.8 | E12: 29.3 | F12: 32.7 | G12: 36.3 | H12: 40.5 | I12: 46.2 | J12: 51 | K12: 55.7 | L12: 60.3 | M12: 64.6 | N12: 68.4 | O12: 72.6 | P12: 76.3 | Q12: 80.6 | R12: 84.3 | S12: 87.8 | T12: 91.3 | U12: 94.3 | V12: 97.1 | W12: 99.7 | X12: 102.1 | Y12: 104.5 | Z12: 106.8
B13: SME | C13: 0.2 | D13: 0.3 | E13: 0.4 | F13: 0.5 | G13: 0.6 | H13: 0.8 | I13: 1.1 | J13: 1.4 | K13: 1.6 | L13: 2 | M13: 2.3 | N13: 2.5 | O13: 2.7 | P13: 3.1 | Q13: 3.4 | R13: 3.6 | S13: 4 | T13: 4.2 | U13: 4.5 | V13: 4.7 | W13: 4.9 | X13: 5.2 | Y13: 5.6 | Z13: 5.9
B14: Mexico | C14: 0 | D14: 0 | E14: 0 | F14: 0.1 | G14: 0.2 | H14: 0.4 | I14: 0.7 | J14: 1.4 | K14: 2.1 | L14: 2.7 | M14: 3 | N14: 3.2 | O14: 3.2 | P14: 3.6 | Q14: 4.3 | R14: 5.2 | S14: 6.6 | T14: 7.8 | U14: 8.9 | V14: 10 | W14: 11 | X14: 12 | Y14: 13.1 | Z14: 14.1
B15: Colombia | C15: 0 | D15: 0 | E15: 0 | F15: 0 | G15: 0 | H15: 0 | I15: 0 | J15: 0.1 | K15: 0.2 | L15: 0.3 | M15: 0.4 | N15: 0.6 | O15: 0.6 | P15: 0.7 | Q15: 0.8 | R15: 0.8 | S15: 0.9 | T15: 1.3 | U15: 2 | V15: 2.5 | W15: 2.9 | X15: 3.4 | Y15: 3.8 | Z15: 4.2
B17: Number of active customers (# MM) - Nu Holdings
B18: Total | C18: 14 | D18: 15.7 | E18: 18.6 | F18: 21.8 | G18: 25.5 | H18: 29.9 | I18: 35.2 | J18: 41.1 | K18: 46.5 | L18: 52.3 | M18: 57.4 | N18: 61.2 | O18: 64.9 | P18: 68.8 | Q18: 73.8 | R18: 78 | S18: 82.6 | T18: 87.2 | U18: 91.7 | V18: 94.9 | W18: 98.7 | X18: 102.2 | Y18: 105.9 | Z18: 109.3
B19: Credit Card (Consumer + SME) | C19: 11 | D19: 11.4 | E19: 12.6 | F19: 15.3 | G19: 18 | H19: 20.6 | I19: 24.2 | J19: 26.8 | K19: 29.9 | L19: 32.6 | M19: 35.8 | N19: 38.1 | O19: 40.2 | P19: 42.3 | Q19: 44.9 | R19: 46.8 | S19: 48.4 | T19: 49.6 | U19: 50.4 | V19: 53 | W19: 54.6 | X19: 55 | Y19: 56.8 | Z19: 57.6
B20: Unsecured Lending (Consumer + SME) | C20: 0.1 | D20: 0.1 | E20: 0.1 | F20: 0.3 | G20: 0.5 | H20: 0.9 | I20: 1.4 | J20: 2.3 | K20: 2.7 | L20: 4.2 | M20: 5.3 | N20: 5.2 | O20: 6.1 | P20: 6.7 | Q20: 7.3 | R20: 7.1 | S20: 8 | T20: 8.7 | U20: 9.8 | V20: 11.1 | W20: 12.4 | X20: 13.6 | Y20: 14.2 | Z20: 14.4
B22: Payment volume (US$ Bn)
B23: Total PV | C23: 5.1 | D23: 4.1 | E23: 5.7 | F23: 7.6 | G23: 7.5 | H23: 9.9 | I23: 12.1 | J23: 14.4 | K23: 15.9 | L23: 20 | M23: 21.2 | N23: 23.8 | O23: 23.3 | P23: 26.3 | Q23: 28.9 | R23: 32.6 | S23: 31.1 | T23: 31.3 | U23: 30.9 | V23: 32.2 | W23: 30.4 | X23: 33.3 | Y23: 36.5 | Z23: 41.6
B24: Credit Card | C24: 4.6 | D24: 3.6 | E24: 4.6 | F24: 5.8 | G24: 5.6 | H24: 7.2 | I24: 8.4 | J24: 9.6 | K24: 10.6 | L24: 13.1 | M24: 13.6 | N24: 15.1 | O24: 15.1 | P24: 17.1 | Q24: 18.7 | R24: 20.7 | S24: 20.2 | T24: 20.3 | U24: 20 | V24: 20.6 | W24: 19.8 | X24: 21.9 | Y24: 24.2 | Z24: 27.7
B25: Debit Card | C25: 0.5 | D25: 0.5 | E25: 1.1 | F25: 1.8 | G25: 1.8 | H25: 2.7 | I25: 3.7 | J25: 4.8 | K25: 5.3 | L25: 7 | M25: 7.6 | N25: 8.7 | O25: 8.2 | P25: 9.2 | Q25: 10.2 | R25: 11.9 | S25: 10.9 | T25: 11 | U25: 10.9 | V25: 11.6 | W25: 10.6 | X25: 11.4 | Y25: 12.3 | Z25: 13.9
B27: Number of employees (# '000)
B28: Total | C28: 2.6 | D28: 2.7 | E28: 2.7 | F28: 2.9 | G28: 3.3 | H28: 4.5 | I28: 5.4 | J28: 6.1 | K28: 6.9 | L28: 7.7 | M28: 8 | N28: 8 | O28: 7.8 | P28: 7.6 | Q28: 7.6 | R28: 7.7 | S28: 8 | T28: 8.3 | U28: 8.6 | V28: 8.7 | W28: 8.9 | X28: 9.3 | Y28: 9.6 | Z28: 10

Sheet NPLs
B2: Nu Holdings Ltd.
B3: Non-Performing Loans (NPLs)
B4: %
B5: Back to Contents
C9: 43921 | D9: 44012 | E9: 44104 | F9: 44196 | G9: 44286 | H9: 44377 | I9: 44469 | J9: 44561 | K9: 44651 | L9: 44742 | M9: 44834 | N9: 44926 | O9: 45016 | P9: 30/06/2023 | Q9: 30/09/2023 | R9: 31/12/2023 | S9: 31/03/2024 | T9: 30/06/2024 | U9: 30/09/2024 | V9: 31/12/2024 | W9: 31/03/2025 | X9: 30/06/2025 | Y9: 30/09/2025 | Z9: 31/12/2025
B10: Nu Holdings Credit Portfolio
B12: 15-90 days NPL | C12: 0.035 | D12: 0.022 | E12: 0.012 | F12: 0.013 | G12: 0.025 | H12: 0.022 | I12: 0.024 | J12: 0.027 | K12: 0.038 | L12: 0.039 | M12: 0.045 | N12: 0.041 | O12: 0.047 | P12: 0.045 | Q12: 0.044 | R12: 0.042 | S12: 0.051 | T12: 0.047 | U12: 0.045 | V12: 0.042 | W12: 0.048 | X12: 0.045 | Y12: 0.043 | Z12: 0.041
B13: 90+ NPL | C13: 0.05 | D13: 0.062 | E13: 0.053 | F13: 0.037 | G13: 0.029 | H13: 0.028 | I13: 0.031 | J13: 0.031 | K13: 0.034 | L13: 0.04 | M13: 0.046 | N13: 0.051 | O13: 0.053 | P13: 0.058 | Q13: 0.059 | R13: 0.06 | S13: 0.061 | T13: 0.068 | U13: 0.07 | V13: 0.067 | W13: 0.064 | X13: 0.065 | Y13: 0.067 | Z13: 0.066

Sheet FX Rates
B2: Nu Holdings Ltd.
B3: FX Rates
B5: Back to Contents
C9: 44286 | D9: 44377 | E9: 44469 | F9: 44561 | G9: 44651 | H9: 44742 | I9: 44834 | J9: 44926 | K9: 45016 | L9: 30/06/2023 | M9: 30/09/2023 | N9: 31/12/2023 | O9: 31/03/2024 | P9: 30/06/2024 | Q9: 30/09/2024 | R9: 31/12/2024 | S9: 31/03/2025 | T9: 30/06/2025 | U9: 30/09/2025 | V9: 31/12/2025
B10: FX Rates
B12: BRL/USD Average | C12: 5.4856 | D12: 5.2893 | E12: 5.2319 | F12: 5.5851 | G12: 5.225 | H12: 4.9273 | I12: 5.2464 | J12: 5.2588 | K12: 5.1924 | L12: 4.9449 | M12: 4.8851 | N12: 4.9576 | O12: 4.9515 | P12: 5.2154 | Q12: 5.5463 | R12: 5.8402 | S12: 5.8487 | T12: 5.6625 | U12: 5.4493 | V12: 5.3988
B13: BRL/USD End of the Period | C13: 5.6337 | D13: 4.9696 | E13: 5.4429 | F13: 5.5758 | G13: 4.7417 | H13: 5.257 | I13: 5.4155 | J13: 5.2804 | K13: 5.0631 | L13: 4.7854 | M13: 5.0341 | N13: 4.8572 | O13: 5.0145 | P13: 5.5941 | Q13: 5.45 | R13: 6.1736 | S13: 5.7058 | T13: 5.4316 | U13: 5.3217 | V13: 5.4956

Sheet IFRS - Statement of Income
B2: Nu Holdings Ltd.
B3: Consolidated Statement of Profit or Loss - Quarter
B4: Amounts in million of US$, except earnings (loss) per share
B5: Back to Contents
C8: 3-MONTH PERIOD ENDED
C9: 43921 | D9: 44012 | E9: 44104 | F9: 44196 | G9: 44286 | H9: 44377 | I9: 44469 | J9: 44561 | K9: 44651 | L9: 44742 | M9: 44834 | N9: 44926 | O9: 45016 | P9: 45107 | Q9: 45199 | R9: 45291 | S9: 45382 | T9: 45473 | U9: 45565 | V9: 45657 | W9: 45747 | X9: 45838 | Y9: 45930 | Z9: 46022
C10: US$ | D10: US$ | E10: US$ | F10: US$ | G10: US$ | H10: US$ | I10: US$ | J10: US$ | K10: US$ | L10: US$ | M10: US$ | N10: US$ | O10: US$ | P10: US$ | Q10: US$ | R10: US$ | S10: US$ | T10: US$ | U10: US$ | V10: US$ | W10: US$ | X10: US$ | Y10: US$ | Z10: US$
B11: Interest income and gains net of losses on financial instruments | C11: 131.243 | D11: 91.884 | E11: 70.14 | F11: 89.655 | G11: 127.345 | H11: 184.893 | I11: 294.958 | J11: 439.55 | K11: 619.443 | L11: 853.013 | M11: 987.248 | N11: 1095.509 | O11: 1255.454 | P11: 1500.225 | Q11: 1732.699 | R11: 1951.334 | S11: 2280.248 | T11: 2383.307 | U11: 2473.807 | V11: 2493.681 | W11: 2732.136 | X11: 3128.743 | Y11: 3577.478 | Z11: 3996.326
B12: Fee and commission income | C12: 84.912 | D12: 70.443 | E12: 85.946 | F12: 112.91 | G12: 117.718 | H12: 151.195 | I12: 185.949 | J12: 196.415 | K12: 257.824 | L12: 304.548 | M12: 319.619 | N12: 355.027 | O12: 363.213 | P12: 368.415 | Q12: 404.059 | R12: 453.577 | S12: 455.653 | T12: 465.384 | U12: 469.381 | V12: 495.614 | W12: 515.553 | X12: 539.727 | Y12: 595.238 | Z12: 689.54
B13: Total revenue | C13: 216.155 | D13: 162.327 | E13: 156.086 | F13: 202.565 | G13: 245.063 | H13: 336.088 | I13: 480.907 | J13: 635.965 | K13: 877.267 | L13: 1157.561 | M13: 1306.867 | N13: 1450.536 | O13: 1618.667 | P13: 1868.64 | Q13: 2136.758 | R13: 2404.911 | S13: 2735.901 | T13: 2848.691 | U13: 2943.188 | V13: 2989.295 | W13: 3247.689 | X13: 3668.47 | Y13: 4172.716 | Z13: 4685.866
B15: Interest and other financial expenses | C15: -33.23 | D15: -25.321 | E15: -23.984 | F15: -31.389 | G15: -31.743 | H15: -57.236 | I15: -101.393 | J15: -176.972 | K15: -273.003 | L15: -407.5 | M15: -459.889 | N15: -407.511 | O15: -440.212 | P15: -453.426 | Q15: -537.649 | R15: -605.638 | S15: -660.715 | T15: -665.191 | U15: -760.959 | V15: -747.994 | W15: -896.204 | X15: -1029.989 | Y15: -1275.711 | Z15: -1376.776
B16: Transactional expenses | C16: -33.136 | D16: -22.604 | E16: -31.91 | F16: -39.165 | G16: -26.349 | H16: -29.782 | I16: -28.56 | J16: -32.428 | K16: -34.448 | L16: -48.036 | M16: -44.475 | N16: -49.468 | O16: -52.778 | P16: -42.797 | Q16: -56.774 | R16: -63.581 | S16: -62.948 | T16: -64.31 | U16: -59.454 | V16: -73.612 | W16: -58.488 | X16: -78.311 | Y16: -104.99 | Z16: -124.394
B17: Expected credit loss | C17: -61.825 | D17: -19.019 | E17: -32.939 | F17: -55.702 | G17: -71.294 | H17: -82.668 | I17: -127.005 | J17: -199.676 | K17: -275.722 | L17: -338.492 | M17: -375.474 | N17: -415.223 | O17: -474.795 | P17: -590.434 | Q17: -627.506 | R17: -592.483 | S17: -830.719 | T17: -759.765 | U17: -774.144 | V17: -804.355 | W17: -973.544 | X17: -1012.192 | Y17: -977.483 | Z17: -1241.657
B18: Total cost of financial and transactional services provided | C18: -128.191 | D18: -66.944 | E18: -88.833 | F18: -126.256 | G18: -129.386 | H18: -169.686 | I18: -256.958 | J18: -409.076 | K18: -583.173 | L18: -794.028 | M18: -879.838 | N18: -872.202 | O18: -967.785 | P18: -1086.657 | Q18: -1221.929 | R18: -1261.702 | S18: -1554.382 | T18: -1489.266 | U18: -1594.557 | V18: -1625.961 | W18: -1928.236 | X18: -2120.492 | Y18: -2358.184 | Z18: -2742.827
B20: Gross profit | C20: 87.964 | D20: 95.383 | E20: 67.253 | F20: 76.309 | G20: 115.677 | H20: 166.402 | I20: 223.949 | J20: 226.889 | K20: 294.094 | L20: 363.533 | M20: 427.029 | N20: 578.334 | O20: 650.882 | P20: 781.983 | Q20: 914.829 | R20: 1143.209 | S20: 1181.519 | T20: 1359.425 | U20: 1348.631 | V20: 1363.334 | W20: 1319.453 | X20: 1547.978 | Y20: 1814.532 | Z20: 1943.039
B22: Operating (expenses) income | C22: 0 | D22: 0 | E22: 0 | F22: 0 | G22: 0 | H22: 0 | I22: 0 | J22: 0 | K22: 0 | L22: 0 | M22: 0 | N22: 0 | O22: 0 | P22: 0 | Q22: 0 | R22: 0 | S22: 0 | T22: 0 | U22: 0 | V22: 0 | W22: 0 | X22: 0 | Y22: 0 | Z22: 0
B23: Customer support and operations | C23: -40.099 | D23: -26.427 | E23: -28.93 | F23: -28.494 | G23: -32.13 | H23: -40.968 | I23: -51.649 | J23: -65.762 | K23: -61.571 | L23: -77.703 | M23: -90.249 | N23: -105.84 | O23: -107.815 | P23: -113.309 | Q23: -127.295 | R23: -139.663 | S23: -150.612 | T23: -162.917 | U23: -135.196 | V23: -155.918 | W23: -151.475 | X23: -161.434 | Y23: -174.843 | Z23: -164.008
B24: General and administrative expenses (G&A) | C24: -70.624 | D24: -56.979 | E24: -56.788 | F24: -81.633 | G24: -115.848 | H24: -122.295 | I24: -166.527 | J24: -224.231 | K24: -245.108 | L24: -229.505 | M24: -261.778 | N24: -596.876 | O24: -236.881 | P24: -256.408 | Q24: -264.264 | R24: -284.737 | S24: -326.052 | T24: -326.555 | U24: -284.706 | V24: -318.773 | W24: -289.823 | X24: -341.253 | Y24: -349.262 | Z24: -440.122
B25: G&A - Contingent share award (CSA) termination | C25: 0 | D25: 0 | E25: 0 | F25: 0 | G25: 0 | H25: 0 | I25: 0 | J25: 0 | K25: 0 | L25: 0 | M25: 0 | N25: -355.573 | O25: 0 | P25: 0 | Q25: 0 | R25: 0 | S25: 0 | T25: 0 | U25: 0 | V25: 0 | W25: 0 | X25: 0 | Y25: 0 | Z25: 0
... B50: Weighted average number of outstanding shares – Diluted (in thousands of shares) | C50: 1296.708 | D50: 4170.423 | E50: 1320.606 | F50: 1315.578 | G50: 1347.325 | H50: 1366.612 | I50: 1423.876 | J50: 2270.693 | K50: 4660.405 | L50: 4670.972 | M50: 4824.031 | N50: 4692.626 | O50: 4818.2 | P50: 4843.835 | Q50: 4856.845 | R50: 4862.753 | S50: 4886.361 | T50: 4880.953 | U50: 4889.409 | V50: 4894.072 | W50: 4892.628 | X50: 4899.768 | Y50: 4905.133 | Z50: 4907.352

Sheet IFRS - Balance Sheet
B2: Nu Holdings Ltd.
B3: Consolidated Statement of Financial Position
B4: Amounts in million of US$
B5: Back to Contents
C9: 43830 | D9: 44196 | E9: 44286 | F9: 44377 | G9: 44469 | H9: 44561 | I9: 44651 | J9: 44742 | K9: 44834 | L9: 44926 | M9: 45016 | N9: 45107 | O9: 45199 | P9: 45291 | Q9: 45382 | R9: 45473 | S9: 45565 | T9: 45657 | U9: 45747 | V9: 45838 | W9: 45930 | X9: 46022
C10: US$ | D10: US$ | E10: US$ | F10: US$ | G10: US$ | H10: US$ | I10: US$ | J10: US$ | K10: US$ | L10: US$ | M10: US$ | N10: US$ | O10: US$ | P10: US$ | Q10: US$ | R10: US$ | S10: US$ | T10: US$ | U10: US$ | V10: US$ | W10: US$ | X10: US$
B11: Assets
B12: Cash and cash equivalents | C12: 1246.566 | D12: 2343.78 | E12: 2200.663 | F12: 2662.467 | G12: 1996.725 | H12: 2705.675 | I12: 2968.622 | J12: 3701.02 | K12: 3692.793 | L12: 4172.316 | M12: 4310.496 | N12: 6175.049 | O12: 3213.627 | P12: 5923.44 | Q12: 6033.658 | R12: 8530.383 | S12: 7645.754 | T12: 9185.742 | U12: 10284.007 | V12: 13269.017 | W12: 12895.785 | X12: 15003.643
B13: Financial assets at fair value through profit or loss | C13: 2400.691 | D13: 4378.118 | E13: 4405.577 | F13: 5390.216 | G13: 4780.936 | H13: 918.332 | I13: 1037.055 | J13: 967.329 | K13: 780.827 | L13: 133.643 | M13: 109.033 | N13: 182.769 | O13: 119.176 | P13: 389.875 | Q13: 646.131 | R13: 841.256 | S13: 314.885 | T13: 741.042 | U13: 462.853 | V13: 541.468 | W13: 1492.713 | X13: 1140.671
B14: Securities | C14: 2237.673 | D14: 4287.277 | E14: 4356.451 | F14: 5343.289 | G14: 4680.014 | H14: 815.962 | I14: 817.443 | J14: 856.994 | K14: 740.972 | L14: 91.853 | M14: 94.038 | N14: 156.233 | O14: 103.319 | P14: 368.574 | Q14: 624.731 | R14: 813.39 | S14: 119.281 | T14: 665.242 | U14: 335.846 | V14: 397.542 | W14: 1204.982 | X14: 1059.923
B15: Derivatives | C15: 0.241 | D15: 0.08 | E15: 0.034 | F15: 5.845 | G15: 89.543 | H15: 101.318 | I15: 209.439 | J15: 109.934 | K15: 39.552 | L15: 41.485 | M15: 14.686 | N15: 26.223 | O15: 15.541 | P15: 20.981 | Q15: 21.076 | R15: 27.538 | S15: 195.272 | T15: 75.464 | U15: 126.667 | V15: 143.583 | W15: 287.731 | X15: 80.748
B16: Collateral for credit card operations | C16: 162.777 | D16: 90.761 | E16: 49.092 | F16: 41.082 | G16: 11.379 | H16: 1.052 | I16: 10.173 | J16: 0.401 | K16: 0.303 | L16: 0.305 | M16: 0.309 | N16: 0.313 | O16: 0.316 | P16: 0.32 | Q16: 0.324 | R16: 0.328 | S16: 0.332 | T16: 0.336 | U16: 0.34 | V16: 0.343 | W16: 0 | X16: 0
B17: Financial assets at fair value through other comprehensive income | C17: 0 | D17: 0 | E17: 0 | F17: 348.518 | G17: 1837.715 | H17: 8163.428 | I17: 9260.432 | J17: 8850.741 | K17: 8931.961 | L17: 9947.138 | M17: 7916.143 | N17: 7479.797 | O17: 8605.769 | P17: 8805.745 | Q17: 8801.925 | R17: 8156.073 | S17: 11019.2 | T17: 9913.517 | U17: 9901.753 | V17: 10830.505 | W17: 11615.169 | X17: 12157.076
B18: Securities | C18: 0 | D18: 0 | E18: 0 | F18: 348.518 | G18: 1837.715 | H18: 8163.428 | I18: 9260.432 | J18: 8850.741 | K18: 8931.961 | L18: 9947.138 | M18: 7916.143 | N18: 7479.797 | O18: 8605.769 | P18: 8805.745 | Q18: 8801.925 | R18: 8156.073 | S18: 11019.2 | T18: 9913.517 | U18: 9901.753 | V18: 10830.505 | W18: 11615.169 | X18: 12157.076
B19: Financial assets at amortized cost | C19: 2923.676 | D19: 3150.013 | E19: 3172.369 | F19: 4634.392 | G19: 5335.867 | H19: 6982.835 | I19: 9571.139 | J19: 10141.709 | K19: 10908.864 | L19: 13684.484 | M19: 15029.584 | N19: 17135.46 | O19: 20857.39 | P19: 24988.919 | Q19: 25309.564 | R19: 24262.748 | S19: 26240.578 | T19: 26701.505 | U19: 29605.15 | V19: 33707.492 | W19: 37659.426 | X19: 41518.114
B20: Credit card receivables | C20: 2786.524 | D20: 2908.907 | E20: 2787.813 | F20: 3819.891 | G20: 4061.505 | H20: 4780.52 | I20: 6234.824 | J20: 6478.47 | K20: 6987.948 | L20: 8233.072 | M20: 9158.452 | N20: 10387.713 | O20: 10495.524 | P20: 12414.133 | Q20: 12796.677 | R20: 12027.336 | S20: 12689.21 | T20: 12259.276 | U20: 13540.738 | V20: 15129.529 | W20: 16772.45 | X20: 18267.904
B21: Loans to customers | C21: 58.024 | D21: 174.694 | E21: 264.542 | F21: 519.686 | G21: 792.736 | H21: 1194.814 | I21: 1667.517 | J21: 1675.776 | K21: 1603.105 | L21: 1673.44 | M21: 2020.191 | N21: 2433.209 | O21: 2689.978 | P21: 3202.334 | Q21: 3863.812 | R21: 4008.201 | S21: 4939.376 | T21: 5321.885 | U21: 6812.656 | V21: 7870.252 | W21: 8981.758 | X21: 9421.458
B22: Compulsory and other deposits at central banks | C22: 0 | D22: 43.542 | E22: 98.694 | F22: 265.465 | G22: 422.649 | H22: 938.659 | I22: 1333.427 | J22: 1552.139 | K22: 1860.438 | L22: 2778.019 | M22: 2671.668 | N22: 2826.879 | O22: 5849.454 | P22: 7447.483 | Q22: 7005.946 | R22: 6665.907 | S22: 6800.215 | T22: 6743.336 | U22: 7375.537 | V22: 8210.232 | W22: 8166.047 | X22: 9537.788
B23: Interbank transactions | C23: 0.091 | D23: 0 | E23: 1.424 | F23: 4.451 | G23: 19.749 | H23: 0 | I23: 0 | J23: 0 | K23: 0 | L23: 0 | M23: 0 | N23: 0 | O23: 0 | P23: 0 | Q23: 0 | R23: 0 | S23: 0 | T23: 0 | U23: 0 | V23: 0 | W23: 0 | X23: 0
C24: 0 | D24: 0 | E24: 0 | F24: 0 | G24: 0 | H24: 0 | I24: 0 | J24: 0 | K24: 0 | L24: 0 | M24: 0 | N24: 0 | O24: 0 | P24: 0 | Q24: 0 | R24: 0 | S24: 0 | T24: 0 | U24: 0 | V24: 0 | W24: 0 | X24: 0
B25: Securities | C25: 0 | D25: 0 | E25: 0 | F25: 0 | G25: 0 | H25: 0 | I25: 0 | J25: 0 | K25: 0 | L25: 0 | M25: 0 | N25: 0 | O25: 49.673 | P25: 104.42 | Q25: 69.494 | R25: 481.242 | S25: 659.664 | T25: 885.418 | U25: 881.218 | V25: 1407.618 | W25: 2519.531 | X25: 3141.504
B26: Other receivables | C26: 0 | D26: 0 | E26: 0 | F26: 0 | G26: 0 | H26: 50.349 | I26: 285.632 | J26: 374.188 | K26: 381.782 | L26: 521.67 | M26: 1076.681 | N26: 1346.56 | O26: 1600.735 | P26: 1689.03 | Q26: 1405.969 | R26: 954.047 | S26: 971.286 | T26: 1413.443 | U26: 887.63 | V26: 929.533 | W26: 987.844 | X26: 1000.683
B27: Other financial assets | C27: 79.037 | D27: 22.87 | E27: 19.896 | F27: 24.899 | G27: 39.228 | H27: 18.493 | I27: 49.739 | J27: 61.136 | K27: 75.591 | L27: 478.283 | M27: 102.592 | N27: 141.099 | O27: 172.026 | P27: 131.519 | Q27: 167.666 | R27: 126.015 | S27: 180.827 | T27: 78.147 | U27: 107.371 | V27: 160.328 | W27: 231.796 | X27: 148.777
B28: Other assets | C28: 67.931 | D28: 123.495 | E28: 133.004 | F28: 176.253 | G28: 171.17 | H28: 232.915 | I28: 288.115 | J28: 331.383 | K28: 388.604 | L28: 541.903 | M28: 500.225 | N28: 706.514 | O28: 807.622 | P28: 936.209 | Q28: 567.552 | R28: 551.659 | S28: 667.126 | T28: 663.578 | U28: 1113.207 | V28: 1257.643 | W28: 1338.914 | X28: 1403.87
B29: Deferred tax assets | C29: 94.198 | D29: 125.131 | E29: 178.552 | F29: 266.89 | G29: 328.458 | H29: 360.752 | I29: 565.31 | J29: 598.917 | K29: 700.706 | L29: 811.05 | M29: 964.179 | N29: 1224.983 | O29: 1352.275 | P29: 1537.835 | Q29: 1710.214 | R29: 1700.803 | S29: 1898.399 | T29: 1818.339 | U29: 1832.587 | V29: 2055.502 | W29: 2233.675 | X29: 2510.967
B30: Investments in associates | C30: 0 | D30: 0 | E30: 0 | F30: 0 | G30: 0 | H30: 0 | I30: 0 | J30: 0 | K30: 0 | L30: 0 | M30: 0 | N30: 0 | O30: 0 | P30: 0 | Q30: 0 | R30: 0 | S30: 0 | T30: 99.365 | U30: 98.235 | V30: 97.21 | W30: 96.04 | X30: 98.702
B31: Right-of-use assets | C31: 17.195 | D31: 10.66 | E31: 8.977 | F31: 9.142 | G31: 7.454 | H31: 6.426 | I31: 18.994 | J31: 21.888 | K31: 17.301 | L31: 18.982 | M31: 16.811 | N31: 16.414 | O31: 26.027 | P31: 30.459 | Q31: 28.954 | R31: 24.972 | S31: 23.606 | T31: 20.344 | U31: 20.461 | V31: 20.754 | W31: 20.109 | X31: 22.244
B32: Property, plant and equipment | C32: 8.667 | D32: 9.85 | E32: 8.952 | F32: 12.69 | G32: 12.106 | H32: 14.109 | I32: 18.2 | J32: 18.658 | K32: 20.609 | L32: 27.482 | M32: 30.131 | N32: 35.246 | O32: 35.932 | P32: 39.294 | Q32: 36.53 | R32: 31.244 | S32: 29.873 | T32: 25.879 | U32: 25.62 | V32: 25.913 | W32: 25.642 | X32: 27.55
B33: Intangible assets | C33: 1.11 | D33: 12.372 | E33: 12.162 | F33: 59.24 | G33: 61.847 | H33: 72.337 | I33: 120.563 | J33: 147.432 | K33: 167.989 | L33: 182.164 | M33: 215.303 | N33: 254.378 | O33: 277.919 | P33: 295.881 | Q33: 307.399 | R33: 305.99 | S33: 357.64 | T33: 347.616 | U33: 439.835 | V33: 514.293 | W33: 574.972 | X33: 601.669
B34: Goodwill | C34: 0 | D34: 0.831 | E34: 0.831 | F34: 391.706 | G34: 393.82 | H34: 401.872 | I34: 409.573 | J34: 409.604 | K34: 397.334 | L34: 397.397 | M34: 397.486 | N34: 397.473 | O34: 397.505 | P34: 397.538 | Q34: 397.57 | R34: 397.602 | S34: 440.789 | T34: 414.287 | U34: 408.817 | V34: 410.347 | W34: 410.371 | X34: 409.371
B35: Total assets | C35: 6760.034 | D35: 10154.25 | E35: 10121.087 | F35: 13951.514 | G35: 14926.098 | H35: 19858.681 | I35: 24258.003 | J35: 25188.681 | K35: 26006.988 | L35: 29916.559 | M35: 29489.391 | N35: 33608.083 | O35: 35693.242 | P35: 43345.195 | Q35: 43839.497 | R35: 44802.73 | S35: 48637.85 | T35: 49931.214 | U35: 54192.525 | V35: 62730.144 | W35: 68362.816 | X35: 74893.877
B37: Liabilities
B38: Financial liabilities at fair value through profit or loss | C38: 24.125 | D38: 90.796 | E38: 75.279 | F38: 14.884 | G38: 99.169 | H38: 99.334 | I38: 197.305 | J38: 105.065 | K38: 23.147 | L38: 20.932 | M38: 13.276 | N38: 45.481 | O38: 56.491 | P38: 32.161 | Q38: 31.478 | R38: 19.821 | S38: 142.105 | T38: 32.329 | U38: 98.761 | V38: 124.501 | W38: 293.347 | X38: 65.969
B39: Derivatives | C39: 2.041 | D39: 75.304 | E39: 62.216 | F39: 0.122 | G39: 86.638 | H39: 87.278 | I39: 177.079 | J39: 86.511 | K39: 4.048 | L39: 9.425 | M39: 10.344 | N39: 41.715 | O39: 52.775 | P39: 28.173 | Q39: 27.488 | R39: 16.131 | S39: 142.105 | T39: 32.329 | U39: 98.761 | V39: 124.501 | W39: 293.347 | X39: 65.969
B40: Instruments eligible as capital | C40: 22.084 | D40: 15.492 | E40: 13.063 | F40: 14.762 | G40: 12.531 | H40: 12.056 | I40: 20.226 | J40: 18.554 | K40: 19.099 | L40: 11.507 | M40: 2.932 | N40: 3.766 | O40: 3.716 | P40: 3.988 | Q40: 3.99 | R40: 3.69 | S40: 0 | T40: 0 | U40: 0 | V40: 0 | W40: 0 | X40: 0
B41: Financial liabilities at amortized cost | C41: 5972.989 | D41: 9421.71 | E41: 8983.058 | F41: 11602.615 | G41: 12378.683 | H41: 14709.759 | I41: 18668.567 | J41: 19711.995 | K41: 20448.616 | L41: 23646.134 | M41: 23424.829 | N41: 26692.737 | O41: 28196.207 | P41: 34793.213 | Q41: 35859.702 | R41: 36481.096 | S41: 38856.565 | T41: 40227.546 | U41: 43872.763 | V41: 51140.501 | W41: 55234.258 | X41: 60741.103
B42: Deposits | C42: 2693.158 | D42: 5584.862 | E42: 5461.652 | F42: 7505.684 | G42: 8089.835 | H42: 9667.3 | I42: 12596.927 | J42: 13293.235 | K42: 14040.157 | L42: 15808.541 | M42: 15757.663 | N42: 18033.728 | O42: 19117.216 | P42: 23691.13 | Q42: 24254.885 | R42: 25228.578 | S42: 28319.121 | T42: 28855.065 | U42: 31564.365 | V42: 36640.156 | W42: 38775.929 | X42: 41925.101
B43: Payables to network | C43: 2976.505 | D43: 3331.258 | E43: 2982.547 | F43: 3990.411 | G43: 4127.691 | H43: 4882.159 | I43: 5920.795 | J43: 5930.966 | K43: 5894.436 | L43: 7054.783 | M43: 6871.826 | N43: 7749.565 | O43: 7834.854 | P43: 9755.285 | Q43: 9572.521 | R43: 8896.941 | S43: 8556.15 | T43: 9333.541 | U43: 10114.743 | V43: 11160.245 | W43: 11999.389 | X43: 13633.949
B44: Borrowings and financing | C44: 133.401 | D44: 97.454 | E44: 103.22 | F44: 59.165 | G44: 134.398 | H44: 147.243 | I44: 147.645 | J44: 470.881 | K44: 467.959 | L44: 585.568 | M44: 651.181 | N44: 764.522 | O44: 1085.87 | P44: 1136.344 | Q44: 1403.349 | R44: 1735.919 | S44: 1498.931 | T44: 1730.357 | U44: 1706.895 | V44: 2275.618 | W44: 3091.059 | X44: 4398.216
B45: Repurchase agreements | C45: 0 | D45: 0 | E45: 35.508 | F45: 0 | G45: 0 | H45: 3.046 | I45: 3.2 | J45: 16.913 | K45: 46.064 | L45: 197.242 | M45: 144.159 | N45: 144.922 | O45: 158.267 | P45: 210.454 | Q45: 628.947 | R45: 619.658 | S45: 482.363 | T45: 308.583 | U45: 486.76 | V45: 1064.482 | W45: 1367.881 | X45: 783.837
...

Sheet IFRS - Cash Flow
B2: Nu Holdings Ltd.
B3: Consolidated Statement of Cash Flow
B4: Amounts in million of US$
B5: Back to Contents
C9: 43830 | D9: 43921 | E9: 44012 | F9: 44104 | G9: 44196 | H9: 44286 | I9: 44377 | J9: 44469 | K9: 44561 | L9: 44651 | M9: 44742 | N9: 44834 | O9: 44926 | P9: 45016 | Q9: 45107 | R9: 45199 | S9: 45291 | T9: 45382 | U9: 45473 | V9: 45565 | W9: 45657 | X9: 45747 | Y9: 45838 | Z9: 45930 | AA9: 46022
C10: US$ | D10: US$ | E10: US$ | F10: US$ | G10: US$ | H10: US$ | I10: US$ | J10: US$ | K10: US$ | L10: US$ | M10: US$ | N10: US$ | O10: US$ | P10: US$ | Q10: US$ | R10: US$ | S10: US$ | T10: US$ | U10: US$ | V10: US$ | W10: US$ | X10: US$ | Y10: US$ | Z10: US$ | AA10: US$
B11: Cash flows from operating activities
B12: Reconciliation of profit (loss) to net cash flows from operating activities:
B13: Profit (Loss) for the period/year | C13: -92.531 | D13: -33.433 | E13: -31.872 | F13: -64.434 | G13: -171.491 | H13: -49.483 | I13: -64.703 | J13: -99.06 | K13: -165.334 | L13: -45.004 | M13: -74.854 | N13: -67.021 | O13: -364.634 | P13: 141.751 | Q13: 366.617 | R13: 669.653 | S13: 1030.53 | T13: 378.814 | U13: 866.086 | V13: 1419.472 | W13: 1972.112 | X13: 557.208 | Y13: 1194.195 | Z13: 1976.873 | AA13: 2871.672
B14: Adjustments:
B15: Depreciation and amortization | C15: 5.073 | D15: 0.56 | E15: 2.893 | F15: 3.783 | G15: 7.428 | H15: 2.507 | I15: 5.242 | J15: 10.896 | K15: 17.339 | L15: 7.655 | M15: 18.088 | N15: 25.699 | O15: 35.581 | P15: 13.179 | Q15: 27.156 | R15: 46.35 | S15: 62.895 | T15: 18.465 | U15: 36.798 | V15: 56.067 | W15: 77.128 | X15: 21.322 | Y15: 44.392 | Z15: 69.962 | AA15: 97.968
B16: Expected credit loss | C16: 193.967 | D16: 64.181 | E16: 87.43 | F16: 126.184 | G16: 187.79 | H16: 77.21 | I16: 165.815 | J16: 299.404 | K16: 503.679 | L16: 279.489 | M16: 625.185 | N16: 1009.827 | O16: 1440.922 | P16: 491.937 | Q16: 1106.8 | R16: 1784.854 | S16: 2487.648 | T16: 883.498 | U16: 1718.49 | V16: 2569.667 | W16: 3469.044 | X16: 1074.571 | Y16: 2189.754 | Z16: 3304.609 | AA16: 4701.058
B17: Deferred income taxes | C17: -40.34 | D17: -19.404 | E17: -18.613 | F17: -24.079 | G17: -44.025 | H17: -35.392 | I17: -78.958 | J17: -132.732 | K17: -224.654 | L17: -121.699 | M17: -212.71 | N17: -322.255 | O17: -417.612 | P17: -103.986 | Q17: -267.946 | R17: -466.685 | S17: -675.682 | T17: -215.319 | U17: -401.179 | V17: -566.243 | W17: -713.435 | X17: 156.751 | Y17: -40.329 | Z17: -95.425 | AA17: -427.259
B18: Customer program | C18: 0 | D18: 0 | E18: 0 | F18: 0 | G18: 0 | H18: 0 | I18: 0 | J18: 0 | K18: 11.18 | L18: 0 | M18: 0 | N18: 0 | O18: 0 | P18: 0 | Q18: 0 | R18: 0 | S18: 0 | T18: 0 | U18: 0 | V18: 0 | W18: 0 | X18: 0 | Y18: 0 | Z18: 0 | AA18: 0
B19: Provisions and contingent liabilities | C19: 7.386 | D19: 0.131 | E19: 0.154 | F19: 0.338 | G19: 0.227 | H19: 0.338 | I19: 0.32 | J19: 0.502 | K19: 2.818 | L19: -2.147 | M19: -1.958 | N19: -1.382 | O19: -1.174 | P19: 1.239 | Q19: 2.502 | R19: 3.47 | S19: 17.098 | T19: 5.823 | U19: 10.234 | V19: 15.079 | W19: 18.406 | X19: 0.96 | Y19: 2.122 | Z19: 20.264 | AA19: 29.238
B20: Unrealized (gains) losses on financial instruments | C20: 1.799 | D20: -6.524 | E20: -18.584 | F20: 13.067 | G20: 48.433 | H20: 87.09 | I20: 95.216 | J20: 161.37 | K20: 19.338 | L20: 13.508 | M20: 38.458 | N20: 14.063 | O20: 17.794 | P20: 4.437 | Q20: 51.705 | R20: 42.995 | S20: 15.885 | T20: -1.074 | U20: -26.457 | V20: -65.315 | W20: 47.933 | X20: -16.314 | Y20: 56.662 | Z20: -68.824 | AA20: -50.432
B21: Interest accrued | C21: 17.681 | D21: 4.353 | E21: 7.185 | F21: 22.77 | G21: 39.521 | H21: 16.946 | I21: 4.658 | J21: 7.186 | K21: 11.077 | L21: 3.706 | M21: 8.907 | N21: 21.877 | O21: 32.479 | P21: 16.463 | Q21: 40.139 | R21: 68.843 | S21: 103.572 | T21: 41.326 | U21: 72.938 | V21: 147.924 | W21: 179.203 | X21: 47.623 | Y21: 106.059 | Z21: 188.185 | AA21: 288.682
B22: Share-based payments - Contingency share award (CSA) - termination | C22: 0 | D22: 0 | E22: 0 | F22: 0 | G22: 0 | H22: 0 | I22: 0 | J22: 0 | K22: 0 | L22: 0 | M22: 0 | N22: 0 | O22: 355.573 | P22: 0 | Q22: 0 | R22: 0 | S22: 0 | T22: 0 | U22: 0 | V22: 0 | W22: 0 | X22: 0 | Y22: 0 | Z22: 0 | AA22: 0
B23: Share-based compensation | C23: 18.511 | D23: 7.111 | E23: 14.053 | F23: 20.157 | G23: 35.569 | H23: 32.2 | I23: 53.512 | J23: 79.729 | K23: 152.717 | L23: 42.1 | M23: 135.656 | N23: 188.525 | O23: 253.203 | P23: 57.857 | Q23: 116.85 | R23: 168.97 | S23: 212.551 | T23: 78.649 | U23: 158.848 | V23: 224.766 | W23: 272.382 | X23: 77.785 | Y23: 134.836 | Z23: 208.571 | AA23: 271.845
B24: Unrealized losses on other investments | C24: 0 | D24: 0 | E24: 0 | F24: 0 | G24: 0 | H24: 0 | I24: 0 | J24: 0 | K24: -39.28 | L24: -14.055 | M24: -5.067 | N24: -5.067 | O24: 0.848 | P24: 18.298 | Q24: 21.72 | R24: 21.72 | S24: 0.02 | T24: 0 | U24: 0 | V24: 0 | W24: -0.011 | X24: 0 | Y24: 0 | Z24: 0 | AA24: 0
B25: Income of share of profit or (loss) in associates | C25: 0 | D25: 0 | E25: 0 | F25: 0 | G25: 0 | H25: 0 | I25: 0 | J25: 0 | K25: 0 | L25: 0 | M25: 0 | N25: 0 | O25: 0 | P25: 0 | Q25: 0 | R25: 0 | S25: 0 | T25: 0 | U25: 0 | V25: 0 | W25: 0 | X25: 1.13 | Y25: 2.155 | Z25: 3.325 | AA25: 3.689
B26: Others | C26: 0 | D26: 0 | E26: 0 | F26: 0 | G26: 0 | H26: 0 | I26: 0 | J26: 0 | K26: 0 | L26: 0 | M26: 0 | N26: 5.879 | O26: 8.203 | P26: 0 | Q26: 0 | R26: 14.025 | S26: 23.056 | T26: 2.088 | U26: 2.327 | V26: 5.69 | W26: -2.712 | X26: -2.121 | Y26: 13.492 | Z26: 37.718 | AA26: 86.676
C27: 111.546 | D27: 16.975 | E27: 42.646 | F27: 97.786 | G27: 103.452 | H27: 131.416 | I27: 181.102 | J27: 327.295 | K27: 288.88 | L27: 163.553 | M27: 531.705 | N27: 870.145 | O27: 1361.183 | P27: 641.175 | Q27: 1465.543 | R27: 2354.195 | S27: 3277.573 | T27: 1192.27 | U27: 2438.085 | V27: 3807.107 | W27: 5320.05 | X27: 1918.915 | Y27: 3703.338 | Z27: 5645.258 | AA27: 7873.137
B28: Changes in operating assets and liabilities:
B29: Securities | C29: -1689.547 | D29: 102.672 | E29: -178.688 | F29: -865.895 | G29: -2008.861 | H29: -1089.592 | I29: -1238.495 | J29: -2279.875 | K29: -4666.792 | L29: -991.777 | M29: -773.539 | N29: -749.991 | O29: -1102.864 | P29: 1968.358 | Q29: 2221.786 | R29: 1279.337 | S29: 699.076 | T29: -218.559 | U29: -165.656 | V29: -2626.719 | W29: -2552.241 | X29: 335.731 | Y29: -1030.858 | Z29: -3643.301 | AA29: -4812.896
B30: Credit card receivables | C30: -1414.489 | D30: 345.824 | E30: 366.816 | F30: 652.567 | G30: -470.227 | H30: -608.551 | I30: -1066.399 | J30: -1594.432 | K30: -2568.423 | L30: -1576.633 | M30: -2459.157 | N30: -3502.428 | O30: -5213.669 | P30: -1577.046 | Q30: -3246.823 | R30: -5060.879 | S30: -7878.307 | T30: -1740.047 | U30: -2444.542 | V30: -2800.856 | W30: -5873.063 | X30: -2750.317 | Y30: -5562.22 | Z30: -8605.99 | AA30: -12445.835
B31: Loans to customers | C31: -63.009 | D31: -24.499 | E31: -18.514 | F31: -27.279 | G31: -178.686 | H31: -175.395 | I31: -426.329 | J31: -875.629 | K31: -1522.217 | L31: -673.86 | M31: -1145.997 | N31: -1548.747 | O31: -1889.278 | P31: -702.67 | Q31: -1245.332 | R31: -2453.595 | S31: -3577.534 | T31: -1564.023 | U31: -2899.339 | V31: -3529.963 | W31: -7024.003 | X31: -2790.768 | Y31: -5072.2 | Z31: -7706.23 | AA31: -10306.93
B32: Other receivables | C32: 0 | D32: 0 | E32: 0 | F32: 0 | G32: 0 | H32: 0 | I32: 0 | J32: 0 | K32: 0 | L32: 0 | M32: -335.367 | N32: -349.558 | O32: -481.824 | P32: -541.19 | Q32: -778.678 | R32: -1086.236 | S32: -1136.488 | T32: 286.98 | U32: 809.346 | V32: 746.405 | W32: 385.192 | X32: 512.972 | Y32: 456.906 | Z32: 401.17 | AA32: 406.251
B33: Compulsory deposits and others at central banks | C33: 0 | D33: 0 | E33: 0 | F33: 0 | G33: -43.841 | H33: -65.951 | I33: -204.739 | J33: -386.869 | K33: -924.889 | L33: -358.253 | M33: -635.319 | N33: -972.188 | O33: -1880.347 | P33: 103.703 | Q33: -46.123 | R33: -3087.936 | S33: -4540.463 | T33: 447.155 | U33: 859.724 | V33: 672.489 | W33: 805.963 | X33: -616.755 | Y33: -1384.32 | Z33: -1340.493 | AA33: -2749.819
B34: Interbank transactions | C34: -0.091 | D34: 0.093 | E34: -3.142 | F34: -5.008 | G34: 0.093 | H34: -1.462 | I34: -4.106 | J34: -20.153 | K34: 0 | L34: 0 | M34: 0 | N34: 0 | O34: 0 | P34: 0 | Q34: 0 | R34: 0 | S34: 0 | T34: 0 | U34: 0 | V34: 0 | W34: 0 | X34: 0 | Y34: 0 | Z34: 0 | AA34: 0
B35: Other assets | C35: -166.173 | D35: -17.671 | E35: 84.742 | F35: 77.888 | G35: 78.319 | H35: -14.617 | I35: -1.353 | J35: 19.379 | K35: -64.072 | L35: -299.995 | M35: -145.172 | N35: -210.427 | O35: -772.415 | P35: 406.972 | Q35: 163.262 | R35: 33.994 | S35: -60.982 | T35: 334.622 | U35: 426.486 | V35: 223.682 | W35: 369.19 | X35: -467.161 | Y35: -638.178 | Z35: -780.969 | AA35: -828.6
B36: Deposits | C36: 2088.793 | D36: 12.212 | E36: 773.253 | F36: 1529.163 | G36: 2871.246 | H36: 1067.551 | I36: 1579.763 | J36: 2343.522 | K36: 4001.856 | L36: 2658.644 | M36: 3755.012 | N36: 4611.994 | O36: 6278.088 | P36: -49.611 | Q36: 2100.527 | R36: 3326.45 | S36: 7664.82 | T36: 570.928 | U36: 1691.175 | V36: 4808.325 | W36: 5910.612 | X36: 2643.104 | Y36: 7346.845 | Z36: 9347.544 | AA36: 12861.282
B37: Payables to network | C37: 1365.476 | D37: -485.189 | E37: -601.255 | F37: -510.635 | G37: 312.607 | H37: 354.124 | I37: 608.114 | J37: 812.739 | K37: 1602.485 | L37: 942.565 | M37: 1086.143 | N37: 1067.635 | O37: 2221.037 | P37: -178.401 | Q37: 655.859 | R37: 943.798 | S37: 2818.592 | T37: -156.255 | U37: -951.82 | V37: -1266.302 | W37: -528.511 | X37: 734.894 | Y37: 1672.174 | Z37: 2436.827 | AA37: 4132.411
B38: Deferred income | C38: 10.325 | D38: 0.063 | E38: 1.69 | F38: -3.095 | G38: 3.621 | H38: 5.869 | I38: 5.216 | J38: 3.525 | K38: 4.848 | L38: 5.884 | M38: 6.149 | N38: 6.11 | O38: 11.277 | P38: 5.299 | Q38: 12.455 | R38: 19.649 | S38: 25.935 | T38: -0.866 | U38: -6.231 | V38: 3.105 | W38: 3.75 | X38: 13.483 | Y38: 32.712 | Z38: 36.215 | AA38: 5.791
B39: Other liabilities | C39: 52.366 | D39: 0.364 | E39: -1.997 | F39: 32.278 | G39: 57.841 | H39: 111.629 | I39: 128.811 | J39: 278.819 | K39: 417.225 | L39: 144.112 | M39: 230.43 | N39: 423.586 | O39: 979.277 | P39: -134.691 | Q39: 197.455 | R39: 632.384 | S39: 1279.987 | T39: -2.543 | U39: 716.369 | V39: 701.421 | W39: 1111.83 | X39: 878.488 | Y39: 1741.209 | Z39: 2490.96 | AA39: 2659.676
B40: Interest paid | C40: -15.603 | D40: -2.112 | E40: -3.524 | F40: -4.253 | G40: -6.199 | H40: -1.189 | I40: -6.707 | J40: -7.95 | K40: -9.062 | L40: -5.3 | M40: -8.274 | N40: -20.295 | O40: -30.935 | P40: -18.832 | Q40: -36.152 | R40: -64.962 | S40: -82.904 | T40: -36.26 | U40: -56.364 | V40: -87.84 | W40: -88.082 | X40: -20.36 | Y40: -29.312 | Z40: -82.634 | AA40: -92.292
... B43: Cash flows (used in) generated from operating activities | C43: 276.136 | D43: -56.655 | E43: 604.056 | F43: 1168.811 | G43: 974.52 | H43: -222.744 | I43: -273.457 | J43: -1065.191 | K43: -2928.925 | L43: 78.302 | M43: 542.632 | N43: 527.22 | O43: 755.573 | P43: 94.292 | Q43: 1794.059 | R43: -1440.302 | S43: 1266.189 | T43: -570.619 | U43: 2097.809 | V43: 1028.947 | W43: 2399.044 | X43: 1085.345 | Y43: 3640.032 | Z43: 2669.433 | AA43: 3500.464
B45: Cash flows from investing activities
B46: Acquisition of property, plant and equipment | C46: -2.377 | D46: -0.245 | E46: -1.522 | F46: -1.738 | G46: -3.084 | H46: -1.779 | I46: -2.01 | J46: -2.544 | K46: -6.025 | L46: -4.683 | M46: -7.425 | N46: -11.396 | O46: -20.001 | P46: -4.596 | Q46: -11.403 | R46: -15.453 | S46: -20.243 | T46: -0.21 | U46: 3.401 | V46: 2.307 | W46: -5.418 | X46: -2.4 | Y46: -4.394 | Z46: -6.949 | AA46: -7.215
B47: Acquisition and development of intangible assets | C47: -2.302 | D47: 0 | E47: -1.322 | F47: -3.385 | G47: -4.902 | H47: -3.424 | I47: -3.492 | J47: -12.579 | K47: -22.473 | L47: -10.059 | M47: -45.611 | N47: -75.22 | O47: -94.305 | P47: -41.919 | Q47: -87.257 | R47: -130.683 | S47: -156.76 | T47: -26.573 | U47: -43.611 | V47: -79.377 | W47: -169.572 | X47: -80.115 | Y47: -148.499 | Z47: -271.213 | AA47: -333.554
...

Sheet IFRS - Revenue breakdown 
B2: Nu Holdings Ltd.
B3: Revenue Breakdown
B4: Amounts in million of US$
B5: Back to Contents
C8: 3-MONTH PERIOD ENDED
C9: 43921 | D9: 44012 | E9: 44104 | F9: 44196 | G9: 44286 | H9: 44377 | I9: 44469 | J9: 44561 | K9: 44651 | L9: 44742 | M9: 44834 | N9: 44926 | O9: 45016 | P9: 45107 | Q9: 45199 | R9: 45291 | S9: 45382 | T9: 45473 | U9: 45565 | V9: 45657 | W9: 45747 | X9: 45838 | Y9: 45930 | Z9: 46022
C10: US$ | D10: US$ | E10: US$ | F10: US$ | G10: US$ | H10: US$ | I10: US$ | J10: US$ | K10: US$ | L10: US$ | M10: US$ | N10: US$ | O10: US$ | P10: US$ | Q10: US$ | R10: US$ | S10: US$ | T10: US$ | U10: US$ | V10: US$ | W10: US$ | X10: US$ | Y10: US$ | Z10: US$
B11: Interest income – credit card | C11: 69.4 | D11: 58.533 | E11: 41.569 | F11: 48.003 | G11: 61.442 | H11: 83.075 | I11: 94.054 | J11: 119.26 | K11: 189.52 | L11: 243.916 | M11: 262.207 | N11: 319.232 | O11: 447.696 | P11: 593.855 | Q11: 679.746 | R11: 800.595 | S11: 983.573 | T11: 985.139 | U11: 966.663 | V11: 866.991 | W11: 951.569 | X11: 1091.598 | Y11: 1219.239 | Z11: 1335.364
B12: Interest income – loan | C12: 7.563 | D12: 6.234 | E12: 8.406 | F12: 16.723 | G12: 29.52 | H12: 47.125 | I12: 84.579 | J12: 131.477 | K12: 194.147 | L12: 228.035 | M12: 250.443 | N12: 259.571 | O12: 286.943 | P12: 353.082 | Q12: 453.415 | R12: 556.881 | S12: 655.961 | T12: 730.002 | U12: 787.051 | V12: 865.649 | W12: 1007.239 | X12: 1128.02 | Y12: 1252.363 | Z12: 1396.641
B13: Interest income – other assets at amortized cost | C13: 9.082 | D13: 9.254 | E13: 9.515 | F13: 9.982 | G13: 8.519 | H13: 13.35 | I13: 19.512 | J13: 24.821 | K13: 40.946 | L13: 95.449 | M13: 129.556 | N13: 122.785 | O13: 154.163 | P13: 191.446 | Q13: 236.609 | R13: 269.019 | S13: 260.222 | T13: 281.814 | U13: 324.251 | V13: 412.693 | W13: 414.845 | X13: 498.61 | Y13: 610.272 | Z13: 760.867
B14: Interest income – other receivables | C14: 0 | D14: 0 | E14: 0 | F14: 0 | G14: 0 | H14: 2.116 | I14: 4.469 | J14: 10.651 | K14: 0 | L14: 32.108 | M14: 50.162 | N14: 78.734 | O14: 86.971 | P14: 96.609 | Q14: 111.465 | R14: 103.491 | S14: 103.816 | T14: 77.726 | U14: 73.117 | V14: 69.537 | W14: 70.815 | X14: 94.175 | Y14: 95.11 | Z14: 101.575
B15: Interest income and gains net of losses - financial instruments at fair value | C15: 43.469 | D15: 17.843 | E15: 11.483 | F15: 12.024 | G15: 25.715 | H15: 38.46 | I15: 92.053 | J15: 152.968 | K15: 194.9 | L15: 264.464 | M15: 308.569 | N15: 319.686 | O15: 271.194 | P15: 245.759 | Q15: 257.323 | R15: 198.753 | S15: 289.557 | T15: 351.149 | U15: 318.593 | V15: 328.692 | W15: 256.729 | X15: 296.219 | Y15: 391.787 | Z15: 414.813
B16: Other income at fair value | C16: 1.729 | D16: 0.02 | E16: -0.833 | F16: 2.923 | G16: 2.149 | H16: 0.767 | I16: 0.291 | J16: 0.373 | K16: -0.07 | L16: -10.959 | M16: -13.689 | N16: -4.499 | O16: 8.487 | P16: 19.474 | Q16: -5.859 | R16: 22.595 | S16: -12.881 | T16: -42.523 | U16: 4.132 | V16: -49.881 | W16: 30.939 | X16: 20.121 | Y16: 8.707 | Z16: -12.934
B17: Total interest income and gains net of losses on financial instruments | C17: 131.243 | D17: 91.884 | E17: 70.14 | F17: 89.655 | G17: 127.345 | H17: 184.893 | I17: 294.958 | J17: 439.55 | K17: 619.443 | L17: 853.013 | M17: 987.248 | N17: 1095.509 | O17: 1255.454 | P17: 1500.225 | Q17: 1732.699 | R17: 1951.334 | S17: 2280.248 | T17: 2383.307 | U17: 2473.807 | V17: 2493.681 | W17: 2732.136 | X17: 3128.743 | Y17: 3577.478 | Z17: 3996.326
B19: Credit and debit card income | C19: 61.723 | D19: 48.294 | E19: 62.435 | F19: 81.875 | G19: 83.617 | H19: 107.357 | I19: 130.469 | J19: 150.062 | K19: 189.506 | L19: 224.437 | M19: 244.229 | N19: 259.201 | O19: 265.38 | P19: 277.805 | Q19: 302.504 | R19: 342.168 | S19: 339.703 | T19: 344.4 | U19: 337.367 | V19: 359.107 | W19: 372.384 | X19: 392.568 | Y19: 435.96 | Z19: 519.366
B20: Late fees | C20: 9.086 | D20: 7.535 | E20: 6.353 | F20: 8.263 | G20: 9.651 | H20: 11.376 | I20: 13.315 | J20: 15.609 | K20: 20.701 | L20: 25.515 | M20: 17.917 | N20: 40.366 | O20: 36.359 | P20: 42.866 | Q20: 46.874 | R20: 54.589 | S20: 61.744 | T20: 70.49 | U20: 76.178 | V20: 79.071 | W20: 84.614 | X20: 90.193 | Y20: 101.839 | Z20: 108.359
B21: Insurance commission | C21: 0 | D21: 0 | E21: 0 | F21: 0 | G21: 0 | H21: 0 | I21: 0 | J21: 0 | K21: 0 | L21: 0 | M21: 0 | N21: 0 | O21: 0 | P21: 5.86 | Q21: 0 | R21: 0 | S21: 6.966 | T21: 6.427 | U21: 7.623 | V21: 8.082 | W21: 8.275 | X21: 8.493 | Y21: 9.182 | Z21: 9.58
B22: Other fee and commission income | C22: 14.103 | D22: 14.614 | E22: 17.158 | F22: 22.772 | G22: 24.45 | H22: 32.462 | I22: 42.165 | J22: 41.924 | K22: 47.617 | L22: 54.596 | M22: 57.473 | N22: 55.46 | O22: 61.474 | P22: 41.884 | Q22: 54.681 | R22: 56.82 | S22: 47.24 | T22: 44.067 | U22: 48.213 | V22: 49.354 | W22: 50.28 | X22: 48.473 | Y22: 48.257 | Z22: 52.235
B23: Customer Program ("NuSócios") | C23: 0 | D23: 0 | E23: 0 | F23: 0 | G23: 0 | H23: 0 | I23: 0 | J23: -11.18 | K23: 0 | L23: 0 | M23: 0 | N23: 0 | O23: 0 | P23: 0 | Q23: 0 | R23: 0 | S23: 0 | T23: 0 | U23: 0 | V23: 0 | W23: 0 | X23: 0 | Y23: 0 | Z23: 0
B24: Total fee and commission income | C24: 84.912 | D24: 70.443 | E24: 85.946 | F24: 112.91 | G24: 117.718 | H24: 151.195 | I24: 185.949 | J24: 196.415 | K24: 257.824 | L24: 304.548 | M24: 319.619 | N24: 355.027 | O24: 363.213 | P24: 368.415 | Q24: 404.059 | R24: 453.577 | S24: 455.653 | T24: 465.384 | U24: 469.381 | V24: 495.614 | W24: 515.553 | X24: 539.727 | Y24: 595.238 | Z24: 689.54

Sheet IFRS - Expenses breakdown
B2: Nu Holdings Ltd.
B3: Expenses Breakdown
B4: Amounts in million of US$
B5: Back to Contents
C8: 3-MONTH PERIOD ENDED
C9: 43921 | D9: 44012 | E9: 44104 | F9: 44196 | G9: 44286 | H9: 44377 | I9: 44469 | J9: 44561 | K9: 44651 | L9: 44742 | M9: 44834 | N9: 44926 | O9: 45016 | P9: 45107 | Q9: 45199 | R9: 45291 | S9: 45382 | T9: 45473 | U9: 45565 | V9: 45657 | W9: 45747 | X9: 45838 | Y9: 45930 | Z9: 46022
C10: US$ | D10: US$ | E10: US$ | F10: US$ | G10: US$ | H10: US$ | I10: US$ | J10: US$ | K10: US$ | L10: US$ | M10: US$ | N10: US$ | O10: US$ | P10: US$ | Q10: US$ | R10: US$ | S10: US$ | T10: US$ | U10: US$ | V10: US$ | W10: US$ | X10: US$ | Y10: US$ | Z10: US$
B11: Interest expense on deposits | C11: 26.113 | D11: 20.033 | E11: 19.108 | F11: 22.071 | G11: 25.416 | H11: 49.128 | I11: 91.098 | J11: 151.778 | K11: 247.218 | L11: 362.842 | M11: 430.356 | N11: 367.482 | O11: 395.116 | P11: 401.073 | Q11: 463.685 | R11: 463.965 | S11: 514.071 | T11: 550.281 | U11: 623.569 | V11: 654.306 | W11: 761.167 | X11: 920.052 | Y11: 1089.722 | Z11: 1105.603
B12: Interest expense on debt instruments and financing | C12: 0 | D12: 0 | E12: 0 | F12: 0 | G12: 0 | H12: 0 | I12: 0 | J12: 0 | K12: 0 | L12: 0 | M12: 0 | N12: 0 | O12: 5.729 | P12: 0 | Q12: 0 | R12: 0 | S12: 30.521 | T12: 38.909 | U12: 129.112 | V12: 60.888 | W12: 62.727 | X12: 52.582 | Y12: 121.081 | Z12: 193.303
